Workbook

Sheet Funder Database April
A1: Funder ID | B1: Donor Name | C1: Organization | D1: Donor Type | E1: Stage | F1: Status | G1: Primary Contact Email | H1: Phone | I1: Region | J1: Giving Level | K1: First Gift Date | L1: First Gift Amount | M1: FY2023 Giving | N1: FY2024 Giving | O1: FY2025 Giving | P1: FY2026 Giving (YTD) | Q1: Lifetime Giving | R1: Multi-Year Pledge? | S1: Pledge Total | T1: Pledge Start FY | U1: Pledge End FY | V1: Current Pledge Year | W1: Annual Pledge Amount | X1: Fund / DAF | Y1: Gift Designation | Z1: Stewardship Owner | AA1: Last Contact Date | AB1: Last Contact Type | AC1: Next Action | AD1: Next Action Date | AE1: Board Member? | AF1: Advisory Council? | AG1: Event Attendance (Last 12mo) | AH1: Capacity Rating | AI1: Likelihood Rating | AJ1: Priority Score | AK1: Notes | AL1: Account Owner
A2: F-001 | B2: David & Rachel Kim | C2: Kim Family Trust | D2: Individual/Family | E2: Stewardship | F2: Active | G2: david.kim@kimfamilytrust.org | H2: (310) 555-6243 | I2: West Coast | J2: Transformational | K2: 03/15/2016 | L2: 100000 | M2: 350000 | N2: 400000 | O2: 450000 | P2: 500000 | Q2: =SUM(M2:P2) -> 1700000 | R2: Yes | S2: 2500000 | T2: FY2022 | U2: FY2027 | V2: 5 of 6 | W2: 450000 | X2: Kim Family DAF - Goldman Sachs Philanthropy Fund | Y2: Unrestricted / West Coast Initiative | Z2: Sarah Mitchell | AA2: 03/12/2026 | AB2: In-person meeting | AC2: Cultivation event planning at Kim residence | AD2: 05/01/2026 | AE2: No | AF2: No | AG2: 3 | AH2: A ($1M+) | AI2: Very High | AJ2: 10 | AK2: 10-year donor. Interested in West Coast expansion. Rachel hosting May gala cultivation event. | AL2: Lisa
A3: F-002 | B3: Margaret Chen | C3: Chen Family Foundation | D3: Foundation | E3: Stewardship | F3: Active | G3: margaret.chen@chenfamilyfdn.org | H3: (415) 555-2891 | I3: West Coast | J3: Major | K3: 09/20/2019 | L3: 50000 | M3: 150000 | N3: 200000 | O3: 250000 | P3: 250000 | Q3: =SUM(M3:P3) -> 850000 | R3: Yes | S3: 1250000 | T3: FY2024 | U3: FY2028 | V3: 3 of 5 | W3: 250000 | X3: Chen Family DAF - Fidelity Charitable | Y3: STEM Education | Z3: Sarah Mitchell | AA3: 02/28/2026 | AB3: Phone call | AC3: Finalize advisory board invitation | AD3: 04/15/2026 | AE3: No | AF3: Pending | AG3: 2 | AH3: A ($1M+) | AI3: High | AJ3: 9 | AK3: Connected us with Priya Ramanathan. Interested in advisory board. | AL3: Rafaela
A4: F-003 | B4: Alicia Gutierrez-Santos | C4: Santos Foundation | D4: Foundation | E4: Stewardship | F4: Active | G4: alicia@santosfoundation.org | H4: (713) 555-3476 | I4: Southwest | J4: Major | K4: 06/10/2021 | L4: 75000 | M4: 100000 | N4: 120000 | O4: 150000 | P4: 180000 | Q4: =SUM(M4:P4) -> 550000 | R4: Yes | S4: 900000 | T4: FY2024 | U4: FY2028 | V4: 3 of 5 | W4: 180000 | X4: Santos Foundation DAF - National Philanthropic Trust | Y4: STEM Education Pipeline | Z4: Maria Lopez | AA4: 03/05/2026 | AB4: Email | AC4: Coordinate joint site visit with Sandra Okonkwo | AD4: 04/20/2026 | AE4: No | AF4: No | AG4: 2 | AH4: B ($500K-$1M) | AI4: Very High | AJ4: 9 | AK4: Earmarked for STEM pipeline. Wants quarterly impact reports. Suggested joint site visit with Okonkwo. | AL4: Jack
A5: F-004 | B5: Robert Blackwell III | C5: Blackwell Industries | D5: Corporate | E5: Cultivation | F5: Active | G5: r.blackwell@blackwellindustries.com | H5: (212) 555-7634 | I5: Northeast | J5: Major | K5: 01/22/2026 | L5: 150000 | M5: 0 | N5: 0 | O5: 0 | P5: 150000 | Q5: =SUM(M5:P5) -> 150000 | R5: No | X5: Blackwell Giving Fund - Schwab Charitable | Y5: Northeast Programs | Z5: James Wright | AA5: 02/15/2026 | AB5: In-person meeting | AC5: Schedule second meeting; discuss multi-year | AD5: 04/30/2026 | AE5: No | AF5: No | AG5: 1 | AH5: A ($1M+) | AI5: Medium | AJ5: 8 | AK5: First-time major donor. Board referral from Thomas Fitzgerald. High capacity prospect. | AL5: Lisa
A6: F-005 | B6: James & Dorothy Whitfield | C6: Whitfield Group | D6: Individual/Family | E6: Stewardship | F6: Active | G6: jwhitfield@whitfieldgroup.net | H6: (312) 555-8819 | I6: Midwest | J6: Major | K6: 11/01/2018 | L6: 50000 | M6: 75000 | N6: 85000 | O6: 100000 | P6: 100000 | Q6: =SUM(M6:P6) -> 360000 | R6: Yes | S6: 500000 | T6: FY2024 | U6: FY2028 | V6: 3 of 5 | W6: 100000 | X6: Whitfield Family DAF - Vanguard Charitable | Y6: Unrestricted | Z6: Sarah Mitchell | AA6: 01/20/2026 | AB6: Holiday card + call | AC6: Annual renewal meeting | AD6: 09/15/2026 | AE6: No | AF6: No | AG6: 1 | AH6: B ($500K-$1M) | AI6: Very High | AJ6: 9 | AK6: Steady annual renewal. Very loyal. | AL6: Lisa
A7: F-006 | B7: Naomi Ashford | C7: Ashford Philanthropic Group | D7: Foundation | E7: Stewardship | F7: Active | G7: nashford@ashfordphilanthropy.org | H7: (503) 555-7789 | I7: Pacific NW | J7: Major | K7: 04/22/2020 | L7: 60000 | M7: 80000 | N7: 100000 | O7: 110000 | P7: 125000 | Q7: =SUM(M7:P7) -> 415000 | R7: Yes | S7: 625000 | T7: FY2024 | U7: FY2028 | V7: 3 of 5 | W7: 125000 | X7: Ashford DAF - BNY Mellon | Y7: Rural Program Expansion | Z7: Maria Lopez | AA7: 03/15/2026 | AB7: Email | AC7: Send Q1 impact report | AD7: 04/10/2026 | AE7: No | AF7: Yes | AG7: 2 | AH7: B ($500K-$1M) | AI7: High | AJ7: 8 | AK7: Earmarked for rural expansion. Very engaged with program outcomes. | AL7: Rafaela
A8: F-007 | B8: Priya Ramanathan | C8: Ramanathan & Associates | D8: Corporate | E8: Stewardship | F8: Active | G8: priya@ramanathan-assoc.com | H8: (617) 555-4102 | I8: Northeast | J8: Mid-Level | K8: 08/15/2022 | L8: 25000 | M8: 25000 | N8: 35000 | O8: 50000 | P8: 75000 | Q8: =SUM(M8:P8) -> 185000 | R8: No | X8: Direct | Y8: STEM Education | Z8: James Wright | AA8: 02/03/2026 | AB8: Email | AC8: Thank you + impact report | AD8: 04/15/2026 | AE8: No | AF8: No | AG8: 1 | AH8: C ($100K-$500K) | AI8: High | AJ8: 7 | AK8: Referred by Margaret Chen. Increased from $50K to $75K this year. | AL8: Jack
A9: F-008 | B9: Michael & Patricia Novak | C9: Novak Family Foundation | D9: Foundation | E9: Stewardship | F9: Active | G9: mnovak@novakfamilyfdn.org | H9: (847) 555-4412 | I9: Midwest | J9: Mid-Level | K9: 02/20/2021 | L9: 40000 | M9: 50000 | N9: 65000 | O9: 75000 | P9: 90000 | Q9: =SUM(M9:P9) -> 280000 | R9: No | X9: Novak Family DAF - Community Foundation | Y9: Pell-Eligible Student Scholarships | Z9: Sarah Mitchell | AA9: 03/18/2026 | AB9: Phone call | AC9: Prepare renewal proposal | AD9: 05/01/2026 | AE9: No | AF9: No | AG9: 1 | AH9: B ($500K-$1M) | AI9: High | AJ9: 8 | AK9: Focus on Pell-eligible students in Midwest. Opportunity for programmatic partnership. | AL9: Lisa
A10: F-009 | B10: Sandra Okonkwo | C10: Okonkwo Ventures | D10: Corporate | E10: Cultivation | F10: Active | G10: sokonkwo@okonkwoventures.com | H10: (404) 555-1357 | I10: Southeast | J10: Mid-Level | K10: 02/14/2026 | L10: 50000 | M10: 0 | N10: 0 | O10: 0 | P10: 50000 | Q10: =SUM(M10:P10) -> 50000 | R10: No | X10: Direct | Y10: Scholarship Program | Z10: Maria Lopez | AA10: 02/14/2026 | AB10: Event follow-up | AC10: Joint site visit with Gutierrez-Santos | AD10: 04/20/2026 | AE10: No | AF10: No | AG10: 1 | AH10: C ($100K-$500K) | AI10: Medium | AJ10: 6 | AK10: Event follow-up conversion. Shares interest in scholarship program with Gutierrez-Santos. | AL10: Lisa
A11: F-010 | B11: Thomas Fitzgerald | C11: Fitzgerald & Moore LLP | D11: Corporate | E11: Stewardship | F11: Active | G11: tfitzgerald@fitzmoore.com | H11: (202) 555-9088 | I11: Mid-Atlantic | J11: Mid-Level | K11: 05/10/2020 | L11: 15000 | M11: 15000 | N11: 20000 | O11: 25000 | P11: 25000 | Q11: =SUM(M11:P11) -> 85000 | R11: No | X11: Direct | Y11: Unrestricted + Pro Bono Legal | Z11: James Wright | AA11: 03/01/2026 | AB11: In-person meeting | AC11: Discuss pro bono capacity for next FY | AD11: 04/30/2026 | AE11: No | AF11: No | AG11: 2 | AH11: C ($100K-$500K) | AI11: High | AJ11: 7 | AK11: Also provides pro bono legal support. Referred Robert Blackwell III. | AL11: Jack
A12: F-011 | B12: William R. Thornton | C12: Thornton Capital Partners | D12: Corporate | E12: Qualification | F12: Prospect | G12: wthornton@thorntoncap.com | H12: (646) 555-5521 | I12: Northeast | J12: Mid-Level | K12: 10/05/2025 | L12: 60000 | M12: 0 | N12: 0 | O12: 60000 | P12: 60000 | Q12: =SUM(M12:P12) -> 120000 | R12: No | X12: Direct | Y12: Unrestricted | Z12: James Wright | AA12: 03/10/2026 | AB12: In-person meeting | AC12: Prepare board nomination package | AD12: 04/15/2026 | AE12: No | AF12: No | AG12: 2 | AH12: A ($1M+) | AI12: Medium | AJ12: 8 | AK12: Strong board prospect. Requested meeting with ED. Deepening engagement since fall reception. | AL12: Lisa
A13: F-012 | B13: Evelyn Tran | C13: Tran Holdings LLC | D13: Corporate | E13: Cultivation | F13: Prospect | G13: evelyn.tran@tranholdings.com | H13: (408) 555-2106 | I13: West Coast | J13: Entry | K13: 12/01/2025 | L13: 35000 | M13: 0 | N13: 0 | O13: 35000 | P13: 35000 | Q13: =SUM(M13:P13) -> 70000 | R13: No | X13: Direct | Y13: Alumni Scholarship | Z13: Sarah Mitchell | AA13: 03/22/2026 | AB13: Email | AC13: Follow up on named scholarship fund interest | AD13: 04/30/2026 | AE13: No | AF13: No | AG13: 1 | AH13: A ($1M+) | AI13: Low | AJ13: 7 | AK13: Alumni, Class of 2005. Company just completed Series C. Interested in named scholarship fund. | AL13: Lisa
A14: F-013 | B14: Hiroshi Tanaka | C14: Tanaka Biotech Inc. | D14: Corporate | E14: Identification | F14: Prospect | G14: htanaka@tanakabiotech.com | H14: (858) 555-3891 | I14: West Coast | J14: None | M14: 0 | N14: 0 | O14: 0 | P14: 0 | Q14: =SUM(M14:P14) -> 0 | R14: No | Y14: STEM Education | Z14: Maria Lopez | AA14: 01/10/2026 | AB14: Research | AC14: Request intro through Margaret Chen | AD14: 04/15/2026 | AE14: No | AF14: No | AG14: 0 | AH14: A ($1M+) | AI14: Low | AJ14: 7 | AK14: UC San Diego connection. Biotech IPO 2024. Interested in STEM education per public statements. | AL14: Lisa
A15: F-014 | B15: Denise & Marcus Hargrove | C15: Hargrove Family Fund | D15: Individual/Family | E15: Identification | F15: Prospect | G15: dhargrove@hargrovefund.org | H15: (404) 555-8822 | I15: Southeast | J15: None | M15: 0 | N15: 0 | O15: 0 | P15: 0 | Q15: =SUM(M15:P15) -> 0 | R15: No | Z15: James Wright | AA15: 12/15/2025 | AB15: Research | AC15: Outreach via annual appeal mailing | AD15: 05/01/2026 | AE15: No | AF15: No | AG15: 0 | AH15: B ($500K-$1M) | AI15: Low | AJ15: 6 | AK15: Atlanta-based philanthropy family. Focus on education equity. Identified via peer screening. | AL15: Jack
A16: F-015 | B16: Victoria Langston-Reed | C16: Reed Foundation | D16: Foundation | E16: Solicitation | F16: Prospect | G16: vlreed@reedfoundation.org | H16: (617) 555-6100 | I16: Northeast | J16: None | M16: 0 | N16: 0 | O16: 0 | P16: 0 | Q16: =SUM(M16:P16) -> 0 | R16: No | Y16: Scholarship / General | Z16: Sarah Mitchell | AA16: 03/28/2026 | AB16: Proposal submitted | AC16: Await foundation board decision | AD16: 06/01/2026 | AE16: No | AF16: No | AG16: 1 | AH16: A ($1M+) | AI16: Medium | AJ16: 8 | AK16: $200K proposal submitted for scholarship endowment. Foundation board meets quarterly. | AL16: Lisa
A17: F-016 | B17: Gregory & Susan Patel | C17: Patel Family Trust | D17: Individual/Family | E17: Re-engagement | F17: Lapsed | G17: gpatel@patelfamilytrust.org | H17: (312) 555-2200 | I17: Midwest | J17: Mid-Level | K17: 06/01/2018 | L17: 25000 | M17: 50000 | N17: 40000 | O17: 0 | P17: 0 | Q17: =SUM(M17:P17) -> 90000 | R17: No | X17: Patel Family DAF - Schwab | Y17: Unrestricted | Z17: James Wright | AA17: 11/20/2025 | AB17: Phone call (voicemail) | AC17: Send personalized re-engagement letter | AD17: 04/10/2026 | AE17: No | AF17: Yes (Former) | AG17: 0 | AH17: B ($500K-$1M) | AI17: Medium | AJ17: 7 | AK17: Last gift FY2024. Missed FY2025 renewal. Was on advisory council. Personal outreach needed. | AL17: Lisa
A18: F-017 | B18: Diana Kowalski | C18: Kowalski Media Group | D18: Corporate | E18: Re-engagement | F18: Lapsed | G18: dkowalski@kowalskimedia.com | H18: (646) 555-4477 | I18: Northeast | J18: Entry | K18: 09/15/2020 | L18: 10000 | M18: 15000 | N18: 10000 | O18: 0 | P18: 0 | Q18: =SUM(M18:P18) -> 25000 | R18: No | X18: Direct | Y18: Unrestricted | Z18: Maria Lopez | AA18: 10/01/2025 | AB18: Email (no response) | AC18: Try phone outreach | AD18: 04/15/2026 | AE18: No | AF18: No | AG18: 0 | AH18: C ($100K-$500K) | AI18: Low | AJ18: 5 | AK18: Last gift FY2024. No response to renewal emails. Try phone. | AL18: Jack
A19: F-018 | B19: Lawrence Bennett | C19: Bennett Capital LLC | D19: Corporate | E19: Closed - Declined | F19: Inactive | G19: lbennett@bennettcap.com | H19: (415) 555-9900 | I19: West Coast | J19: None | M19: 0 | N19: 0 | O19: 0 | P19: 0 | Q19: =SUM(M19:P19) -> 0 | R19: No | Z19: Sarah Mitchell | AA19: 09/15/2025 | AB19: Phone call | AC19: Monitor; revisit in 18 months | AD19: 03/15/2027 | AE19: No | AF19: No | AG19: 1 | AH19: A ($1M+) | AI19: Very Low | AJ19: 6 | AK19: Declined after solicitation meeting. Cited other philanthropic priorities. Polite; door not closed. | AL19: Rafaela
A20: F-019 | B20: Catherine & James Moreau | C20: Moreau Foundation | D20: Foundation | E20: Stewardship | F20: Active | G20: cmoreau@moreaufoundation.org | H20: (504) 555-3321 | I20: Southeast | J20: Major | K20: 01/10/2019 | L20: 80000 | M20: 100000 | N20: 120000 | O20: 140000 | P20: 160000 | Q20: =SUM(M20:P20) -> 520000 | R20: Yes | S20: 800000 | T20: FY2024 | U20: FY2028 | V20: 3 of 5 | W20: 160000 | X20: Moreau Foundation DAF - Fidelity | Y20: First-Generation Student Support | Z20: Sarah Mitchell | AA20: 03/20/2026 | AB20: Phone call | AC20: Discuss program expansion opportunities | AD20: 05/10/2026 | AE20: No | AF20: No | AG20: 2 | AH20: B ($500K-$1M) | AI20: Very High | AJ20: 9 | AK20: New Orleans-based. Deep interest in first-gen students. Annual site visits. | AL20: Jack
A21: F-020 | B21: Richard Cheng | C21: Cheng Dynamics | D21: Corporate | E21: Stewardship | F21: Active | G21: rcheng@chengdynamics.com | H21: (650) 555-8812 | I21: West Coast | J21: Mid-Level | K21: 03/01/2022 | L21: 30000 | M21: 30000 | N21: 45000 | O21: 55000 | P21: 70000 | Q21: =SUM(M21:P21) -> 200000 | R21: No | X21: Direct | Y21: STEM Education | Z21: Maria Lopez | AA21: 02/20/2026 | AB21: Email | AC21: Invite to May gala | AD21: 04/20/2026 | AE21: No | AF21: No | AG21: 2 | AH21: C ($100K-$500K) | AI21: High | AJ21: 7 | AK21: Growing engagement. Employee matching program potential. | AL21: Rafaela
A22: F-021 | B22: Amara Osei-Mensah | C22: Osei-Mensah Family Trust | D22: Individual/Family | E22: Stewardship | F22: Active | G22: aosei@oseimensah.org | H22: (770) 555-6644 | I22: Southeast | J22: Mid-Level | K22: 06/15/2021 | L22: 25000 | M22: 35000 | N22: 40000 | O22: 50000 | P22: 65000 | Q22: =SUM(M22:P22) -> 190000 | R22: No | X22: Osei-Mensah DAF - Vanguard | Y22: Scholarship Program | Z22: James Wright | AA22: 01/30/2026 | AB22: In-person meeting | AC22: Propose multi-year pledge | AD22: 04/25/2026 | AE22: No | AF22: No | AG22: 1 | AH22: B ($500K-$1M) | AI22: High | AJ22: 8 | AK22: Atlanta-based. Increasing annually. Ready for major gift conversation. | AL22: Jack
A23: F-022 | B23: Patricia & Leonard Dubois | C23: Dubois Charitable Fund | D23: Individual/Family | E23: Stewardship | F23: Active | G23: pdubois@duboisfund.org | H23: (617) 555-1198 | I23: Northeast | J23: Major | K23: 09/01/2017 | L23: 75000 | M23: 100000 | N23: 100000 | O23: 100000 | P23: 100000 | Q23: =SUM(M23:P23) -> 400000 | R23: Yes | S23: 500000 | T23: FY2023 | U23: FY2027 | V23: 4 of 5 | W23: 100000 | X23: Dubois DAF - BNY Mellon | Y23: Unrestricted | Z23: Sarah Mitchell | AA23: 12/15/2025 | AB23: Holiday card + call | AC23: Final pledge year discussion; renewal strategy | AD23: 06/01/2026 | AE23: Yes | AF23: No | AG23: 2 | AH23: A ($1M+) | AI23: Very High | AJ23: 10 | AK23: Board member. Entering final pledge year. Need to discuss renewal or increase. | AL23: Lisa
A24: F-023 | B24: Kenji & Yuki Watanabe | C24: Watanabe Group | D24: Corporate | E24: Cultivation | F24: Active | G24: kwatanabe@watanabegroup.co | H24: (206) 555-4455 | I24: Pacific NW | J24: Mid-Level | K24: 11/15/2024 | L24: 40000 | M24: 0 | N24: 0 | O24: 40000 | P24: 55000 | Q24: =SUM(M24:P24) -> 95000 | R24: No | X24: Direct | Y24: Rural Program | Z24: Maria Lopez | AA24: 03/01/2026 | AB24: In-person meeting | AC24: Tour rural program sites | AD24: 05/15/2026 | AE24: No | AF24: No | AG24: 1 | AH24: C ($100K-$500K) | AI24: Medium | AJ24: 6 | AK24: Seattle-based. Second gift indicates deepening. Schedule site visit. | AL24: Lisa
A25: F-024 | B25: Helen Markovich | C25: Markovich Partners LLC | D25: Corporate | E25: Stewardship | F25: Active | G25: hmarkovich@markovichpartners.com | H25: (312) 555-7733 | I25: Midwest | J25: Mid-Level | K25: 04/20/2020 | L25: 20000 | M25: 25000 | N25: 30000 | O25: 35000 | P25: 45000 | Q25: =SUM(M25:P25) -> 135000 | R25: No | X25: Direct | Y25: Unrestricted | Z25: James Wright | AA25: 02/10/2026 | AB25: Email | AC25: Send FY2026 impact summary | AD25: 04/15/2026 | AE25: No | AF25: Yes | AG25: 2 | AH25: C ($100K-$500K) | AI25: High | AJ25: 7 | AK25: Advisory council member. Consistent growth. Midwest business network connections. | AL25: Lisa
A26: F-025 | B26: Raj & Sunita Kapoor | C26: Kapoor Family Foundation | D26: Foundation | E26: Stewardship | F26: Active | G26: rkapoor@kapoorfamilyfdn.org | H26: (713) 555-9922 | I26: Southwest | J26: Major | K26: 02/28/2020 | L26: 50000 | M26: 75000 | N26: 90000 | O26: 100000 | P26: 120000 | Q26: =SUM(M26:P26) -> 385000 | R26: Yes | S26: 600000 | T26: FY2025 | U26: FY2029 | V26: 2 of 5 | W26: 120000 | X26: Kapoor Family DAF - Goldman Sachs | Y26: STEM Education Pipeline | Z26: Maria Lopez | AA26: 03/10/2026 | AB26: Phone call | AC26: Quarterly impact report delivery | AD26: 04/10/2026 | AE26: No | AF26: No | AG26: 2 | AH26: A ($1M+) | AI26: High | AJ26: 9 | AK26: Houston-based. Strong alignment with STEM pipeline. Want to see expansion to Texas. | AL26: Lisa
A27: F-026 | B27: Franklin & Anne Beaumont | C27: Beaumont Group | D27: Individual/Family | E27: Stewardship | F27: Active | G27: fbeaumont@beaumontgroup.com | H27: (214) 555-2288 | I27: Southwest | J27: Mid-Level | K27: 07/01/2021 | L27: 20000 | M27: 25000 | N27: 30000 | O27: 40000 | P27: 50000 | Q27: =SUM(M27:P27) -> 145000 | R27: No | X27: Direct | Y27: General Scholarship | Z27: Sarah Mitchell | AA27: 01/15/2026 | AB27: Holiday card + call | AC27: Annual renewal ask | AD27: 09/01/2026 | AE27: No | AF27: No | AG27: 1 | AH27: C ($100K-$500K) | AI27: High | AJ27: 7 | AK27: Dallas-based. Reliable renewals. Potential for multi-year commitment. | AL27: Jack
A28: F-027 | B28: Nadia El-Amin | C28: El-Amin Consulting Group | D28: Corporate | E28: Stewardship | F28: Active | G28: nelamin@elamingroup.com | H28: (202) 555-6655 | I28: Mid-Atlantic | J28: Entry | K28: 10/01/2023 | L28: 10000 | M28: 0 | N28: 0 | O28: 10000 | P28: 15000 | Q28: =SUM(M28:P28) -> 25000 | R28: No | X28: Direct | Y28: Unrestricted | Z28: James Wright | AA28: 03/15/2026 | AB28: Email | AC28: Cultivation lunch | AD28: 05/01/2026 | AE28: No | AF28: No | AG28: 1 | AH28: C ($100K-$500K) | AI28: Medium | AJ28: 6 | AK28: DC-based consultant. Growing engagement. Connected to policy networks. | AL28: Lisa
A29: F-028 | B29: George & Linda Stratton | C29: Stratton Industries | D29: Corporate | E29: Qualification | F29: Prospect | G29: gstratton@strattonindustries.com | H29: (704) 555-1122 | I29: Southeast | J29: None | M29: 0 | N29: 0 | O29: 0 | P29: 0 | Q29: =SUM(M29:P29) -> 0 | R29: No | Y29: Unrestricted | Z29: James Wright | AA29: 02/01/2026 | AB29: Research | AC29: Request meeting through Thornton connection | AD29: 04/20/2026 | AE29: No | AF29: No | AG29: 0 | AH29: A ($1M+) | AI29: Low | AJ29: 7 | AK29: Charlotte manufacturing. Peer connection through William Thornton. Philanthropic history in education. | AL29: Lisa
A30: F-029 | B30: Isabelle Fontaine | C30: Fontaine Arts & Education Trust | D30: Foundation | E30: Cultivation | F30: Prospect | G30: ifontaine@fontainetrust.org | H30: (415) 555-5567 | I30: West Coast | J30: None | M30: 0 | N30: 0 | O30: 0 | P30: 0 | Q30: =SUM(M30:P30) -> 0 | R30: No | Y30: Arts + STEM Integration | Z30: Sarah Mitchell | AA30: 03/25/2026 | AB30: In-person meeting | AC30: Submit LOI for arts-STEM integration grant | AD30: 05/01/2026 | AE30: No | AF30: No | AG30: 1 | AH30: B ($500K-$1M) | AI30: Medium | AJ30: 7 | AK30: SF-based trust focused on arts and education. Met at conference. Very aligned with new arts-STEM program. | AL30: Lisa
A31: F-030 | B31: Marcus & Tanya Robinson | C31: Robinson Legacy Fund | D31: Individual/Family | E31: Identification | F31: Prospect | G31: mrobinson@robinsonlegacy.org | H31: (404) 555-8890 | I31: Southeast | J31: None | M31: 0 | N31: 0 | O31: 0 | P31: 0 | Q31: =SUM(M31:P31) -> 0 | R31: No | Z31: Maria Lopez | AA31: 01/20/2026 | AB31: Research | AC31: Add to annual gala invite list | AD31: 04/15/2026 | AE31: No | AF31: No | AG31: 0 | AH31: B ($500K-$1M) | AI31: Low | AJ31: 6 | AK31: Atlanta philanthropists. Education equity focus. Identified through Hargrove network. | AL31: Lisa
A32: F-031 | B32: Dr. Angela Vasquez-Torres | C32: Vasquez-Torres Medical Foundation | D32: Foundation | E32: Solicitation | F32: Prospect | G32: avasquez@vtmedfoundation.org | H32: (305) 555-7712 | I32: Southeast | J32: None | M32: 0 | N32: 0 | O32: 0 | P32: 0 | Q32: =SUM(M32:P32) -> 0 | R32: No | Y32: Health Sciences Scholarship | Z32: James Wright | AA32: 03/30/2026 | AB32: Proposal submitted | AC32: Follow up after board review | AD32: 06/15/2026 | AE32: No | AF32: No | AG32: 1 | AH32: B ($500K-$1M) | AI32: Medium | AJ32: 7 | AK32: $150K proposal for health sciences scholarships. Miami-based. Board meets in June. | AL32: Rafaela
A33: F-032 | B33: Arthur & Elaine Worthington | C33: Worthington Trust | D33: Individual/Family | E33: Qualification | F33: Prospect | G33: aworthington@worthingtontrust.com | H33: (860) 555-3344 | I33: Northeast | J33: None | M33: 0 | N33: 0 | O33: 0 | P33: 0 | Q33: =SUM(M33:P33) -> 0 | R33: No | Y33: Endowment | Z33: Sarah Mitchell | AA33: 02/10/2026 | AB33: Phone call | AC33: Schedule campus visit | AD33: 04/25/2026 | AE33: No | AF33: No | AG33: 0 | AH33: A ($1M+) | AI33: Low | AJ33: 7 | AK33: Connecticut old money. Endowment-focused giving. Warm intro from Dubois. | AL33: Jack
A34: F-033 | B34: Carmen Delgado-Ruiz | C34: Delgado Enterprises | D34: Corporate | E34: Cultivation | F34: Prospect | G34: cdelgado@delgadoenterprises.com | H34: (210) 555-4411 | I34: Southwest | J34: Entry | K34: 12/15/2025 | L34: 15000 | M34: 0 | N34: 0 | O34: 0 | P34: 15000 | Q34: =SUM(M34:P34) -> 15000 | R34: No | X34: Direct | Y34: STEM Education | Z34: Maria Lopez | AA34: 12/15/2025 | AB34: Event follow-up | AC34: Schedule coffee meeting | AD34: 04/15/2026 | AE34: No | AF34: No | AG34: 1 | AH34: C ($100K-$500K) | AI34: Medium | AJ34: 6 | AK34: San Antonio-based. Initial gift at holiday event. Tech company founder. STEM aligned. | AL34: Rafaela
A35: F-034 | B35: Howard & Jean Prescott | C35: Prescott Foundation | D35: Foundation | E35: Re-engagement | F35: Lapsed | G35: hprescott@prescottfdn.org | H35: (203) 555-6677 | I35: Northeast | J35: Major | K35: 03/01/2016 | L35: 100000 | M35: 120000 | N35: 100000 | O35: 50000 | P35: 0 | Q35: =SUM(M35:P35) -> 270000 | R35: No | X35: Prescott DAF - Northern Trust | Y35: Unrestricted | Z35: Sarah Mitchell | AA35: 11/01/2025 | AB35: Phone call | AC35: ED personal outreach call | AD35: 04/10/2026 | AE35: No | AF35: Yes (Former) | AG35: 0 | AH35: A ($1M+) | AI35: Medium | AJ35: 8 | AK35: Declined from $120K to $50K in FY2025, then lapsed. Former advisory council. Personal call from ED needed. | AL35: Lisa
A36: F-035 | B36: Tomoko Nakamura | C36: Nakamura Design Studio | D36: Corporate | E36: Re-engagement | F36: Lapsed | G36: tnakamura@nakamuradesign.com | H36: (503) 555-2233 | I36: Pacific NW | J36: Entry | K36: 08/01/2022 | L36: 10000 | M36: 10000 | N36: 15000 | O36: 10000 | P36: 0 | Q36: =SUM(M36:P36) -> 35000 | R36: No | X36: Direct | Y36: Unrestricted | Z36: Maria Lopez | AA36: 09/15/2025 | AB36: Email (no response) | AC36: Send personalized project update | AD36: 04/15/2026 | AE36: No | AF36: No | AG36: 0 | AH36: C ($100K-$500K) | AI36: Low | AJ36: 5 | AK36: Portland designer. Gave 3 years. No response to renewal. Try project-specific appeal. | AL36: Rafaela
A37: F-036 | B37: Robert & Christine Andersen | C37: Andersen Family Fund | D37: Individual/Family | E37: Re-engagement | F37: Lapsed | G37: randersen@andersenfund.org | H37: (952) 555-8811 | I37: Midwest | J37: Mid-Level | K37: 05/15/2019 | L37: 30000 | M37: 40000 | N37: 50000 | O37: 0 | P37: 0 | Q37: =SUM(M37:P37) -> 90000 | R37: No | X37: Andersen DAF - Schwab | Y37: Pell-Eligible Scholarships | Z37: James Wright | AA37: 10/20/2025 | AB37: Phone call (voicemail) | AC37: Handwritten note from scholarship recipient | AD37: 04/20/2026 | AE37: No | AF37: No | AG37: 0 | AH37: B ($500K-$1M) | AI37: Medium | AJ37: 7 | AK37: Minneapolis family. Cared about Pell students. Missed FY2025. Try scholarship recipient story. | AL37: Lisa
A38: F-037 | B38: Martin & Louise Kessler | C38: Kessler Group | D38: Corporate | E38: Closed - Declined | F38: Inactive | G38: mkessler@kesslergroup.com | H38: (212) 555-0099 | I38: Northeast | J38: None | M38: 0 | N38: 0 | O38: 0 | P38: 0 | Q38: =SUM(M38:P38) -> 0 | R38: No | Z38: James Wright | AA38: 06/01/2025 | AB38: In-person meeting | AC38: Revisit in 2027 | AD38: 01/15/2027 | AE38: No | AF38: No | AG38: 0 | AH38: A ($1M+) | AI38: Very Low | AJ38: 6 | AK38: Declined. Company restructuring. Said to revisit in 2 years. | AL38: Jack
A39: F-038 | B39: Diane Zhao | C39: Zhao Capital Management | D39: Corporate | E39: Closed - Declined | F39: Inactive | G39: dzhao@zhaocapital.com | H39: (646) 555-3388 | I39: Northeast | J39: None | M39: 0 | N39: 0 | O39: 0 | P39: 0 | Q39: =SUM(M39:P39) -> 0 | R39: No | Z39: Sarah Mitchell | AA39: 08/15/2025 | AB39: Email | AC39: Add to newsletter; passive cultivation | AD39: 08/15/2026 | AE39: No | AF39: No | AG39: 1 | AH39: B ($500K-$1M) | AI39: Very Low | AJ39: 5 | AK39: Politely declined. Prefers arts funding. Keep on radar for arts-STEM if program launches. | AL39: Lisa
A40: F-039 | B40: Jonathan & Claire Harrington | C40: Harrington Charitable Trust | D40: Individual/Family | E40: Stewardship | F40: Active | G40: jharrington@harringtontrust.org | H40: (617) 555-8834 | I40: Northeast | J40: Major | K40: 05/20/2018 | L40: 60000 | M40: 80000 | N40: 90000 | O40: 100000 | P40: 110000 | Q40: =SUM(M40:P40) -> 380000 | R40: Yes | S40: 550000 | T40: FY2025 | U40: FY2029 | V40: 2 of 5 | W40: 110000 | X40: Harrington DAF - Fidelity | Y40: First-Generation Students | Z40: Sarah Mitchell | AA40: 03/01/2026 | AB40: In-person meeting | AC40: Annual pledge check-in | AD40: 05/20/2026 | AE40: No | AF40: Yes | AG40: 3 | AH40: A ($1M+) | AI40: High | AJ40: 9 | AK40: Boston-based. Advisory council. Strong advocates. Host annual donor dinner. | AL40: Jack
...

Sheet Funder Database March
A1: Funder ID | B1: Donor Name | C1: Organization | D1: Donor Type | E1: Stage | F1: Status | G1: Primary Contact Email | H1: Phone | I1: Region | J1: Giving Level | K1: First Gift Date | L1: First Gift Amount | M1: FY2023 Giving | N1: FY2024 Giving | O1: FY2025 Giving | P1: FY2026 Giving (YTD) | Q1: Lifetime Giving | R1: Multi-Year Pledge? | S1: Pledge Total | T1: Pledge Start FY | U1: Pledge End FY | V1: Current Pledge Year | W1: Annual Pledge Amount | X1: Fund / DAF | Y1: Gift Designation | Z1: Stewardship Owner | AA1: Last Contact Date | AB1: Last Contact Type | AC1: Next Action | AD1: Next Action Date | AE1: Board Member? | AF1: Advisory Council? | AG1: Event Attendance (Last 12mo) | AH1: Capacity Rating | AI1: Likelihood Rating | AJ1: Priority Score | AK1: Notes | AL1: Account Owner
A2: F-001 | B2: David & Rachel Kim | C2: Kim Family Trust | D2: Individual/Family | E2: Solicitation | F2: Active | G2: david.kim@kimfamilytrust.org | H2: (310) 555-6243 | I2: West Coast | J2: Transformational | K2: 03/15/2016 | L2: 100000 | M2: 350000 | N2: 400000 | O2: 450000 | P2: 341200 | Q2: =SUM(M2:P2) -> 1541200 | R2: Yes | S2: 2500000 | T2: FY2022 | U2: FY2027 | V2: 5 of 6 | W2: 450000 | X2: Kim Family DAF - Goldman Sachs Philanthropy Fund | Y2: Unrestricted / West Coast Initiative | Z2: Sarah Mitchell | AA2: 03/12/2026 | AB2: In-person meeting | AC2: Cultivation event planning at Kim residence | AD2: 05/01/2026 | AE2: No | AF2: No | AG2: 3 | AH2: A ($1M+) | AI2: Very High | AJ2: 8 | AK2: 10-year donor. Interested in West Coast expansion. Rachel hosting May gala cultivation event. | AL2: Lisa
A3: F-002 | B3: Margaret Chen | C3: Chen Family Foundation | D3: Foundation | E3: Stewardship | F3: Active | G3: margaret.chen@chenfamilyfdn.org | H3: (415) 555-2891 | I3: West Coast | J3: Major | K3: 09/20/2019 | L3: 50000 | M3: 150000 | N3: 200000 | O3: 250000 | P3: 166900 | Q3: =SUM(M3:P3) -> 766900 | R3: Yes | S3: 1250000 | T3: FY2024 | U3: FY2028 | V3: 3 of 5 | W3: 250000 | X3: Chen Family DAF - Fidelity Charitable | Y3: STEM Education | Z3: Sarah Mitchell | AA3: 02/28/2026 | AB3: Phone call | AC3: Finalize advisory board invitation | AD3: 04/15/2026 | AE3: No | AF3: Pending | AG3: 2 | AH3: A ($1M+) | AI3: High | AJ3: 9 | AK3: Connected us with Priya Ramanathan. Interested in advisory board. | AL3: Rafaela
A4: F-003 | B4: Alicia Gutierrez-Santos | C4: Santos Foundation | D4: Foundation | E4: Stewardship | F4: Active | G4: alicia@santosfoundation.org | H4: (713) 555-3476 | I4: Southwest | J4: Major | K4: 06/10/2021 | L4: 75000 | M4: 100000 | N4: 120000 | O4: 150000 | P4: 122000 | Q4: =SUM(M4:P4) -> 492000 | R4: Yes | S4: 900000 | T4: FY2024 | U4: FY2028 | V4: 3 of 5 | W4: 180000 | X4: Santos Foundation DAF - National Philanthropic Trust | Y4: STEM Education Pipeline | Z4: Maria Lopez | AA4: 03/05/2026 | AB4: Email | AC4: Coordinate joint site visit with Sandra Okonkwo | AD4: 04/20/2026 | AE4: No | AF4: No | AG4: 2 | AH4: B ($500K-$1M) | AI4: Very High | AJ4: 9 | AK4: Earmarked for STEM pipeline. Wants quarterly impact reports. Suggested joint site visit with Okonkwo. | AL4: Jack
A5: F-004 | B5: Robert Blackwell III | C5: Blackwell Industries | D5: Corporate | E5: Cultivation | F5: Active | G5: r.blackwell@blackwellindustries.com | H5: (212) 555-7634 | I5: Northeast | J5: Major | K5: 01/22/2026 | L5: 150000 | M5: 0 | N5: 0 | O5: 0 | P5: 118900 | Q5: =SUM(M5:P5) -> 118900 | R5: No | X5: Blackwell Giving Fund - Schwab Charitable | Y5: Northeast Programs | Z5: James Wright | AA5: 02/15/2026 | AB5: In-person meeting | AC5: Prepare cultivation strategy | AD5: 04/30/2026 | AE5: No | AF5: No | AG5: 1 | AH5: A ($1M+) | AI5: Medium | AJ5: 8 | AK5: First-time major donor. Board referral from Thomas Fitzgerald. High capacity prospect. | AL5: Lisa
A6: F-005 | B6: James & Dorothy Whitfield | C6: Whitfield Group | D6: Individual/Family | E6: Stewardship | F6: Active | G6: jwhitfield@whitfieldgroup.net | H6: (312) 555-8819 | I6: Midwest | J6: Major | K6: 11/01/2018 | L6: 50000 | M6: 75000 | N6: 85000 | O6: 100000 | P6: 61400 | Q6: =SUM(M6:P6) -> 321400 | R6: Yes | S6: 500000 | T6: FY2024 | U6: FY2028 | V6: 3 of 5 | W6: 100000 | X6: Whitfield Family DAF - Vanguard Charitable | Y6: Unrestricted | Z6: Sarah Mitchell | AA6: 01/20/2026 | AB6: Holiday card + call | AC6: Annual renewal meeting | AD6: 09/15/2026 | AE6: No | AF6: No | AG6: 1 | AH6: B ($500K-$1M) | AI6: Very High | AJ6: 9 | AK6: Steady annual renewal. Very loyal. | AL6: Lisa
A7: F-006 | B7: Naomi Ashford | C7: Ashford Philanthropic Group | D7: Foundation | E7: Stewardship | F7: Active | G7: nashford@ashfordphilanthropy.org | H7: (503) 555-7789 | I7: Pacific NW | J7: Major | K7: 04/22/2020 | L7: 60000 | M7: 80000 | N7: 100000 | O7: 110000 | P7: 78600 | Q7: =SUM(M7:P7) -> 368600 | R7: Yes | S7: 625000 | T7: FY2024 | U7: FY2028 | V7: 3 of 5 | W7: 125000 | X7: Ashford DAF - BNY Mellon | Y7: Rural Program Expansion | Z7: Maria Lopez | AA7: 03/15/2026 | AB7: Email | AC7: Send Q1 impact report | AD7: 04/10/2026 | AE7: No | AF7: Yes | AG7: 2 | AH7: B ($500K-$1M) | AI7: High | AJ7: 7 | AK7: Earmarked for rural expansion. Very engaged with program outcomes. | AL7: Rafaela
A8: F-007 | B8: Priya Ramanathan | C8: Ramanathan & Associates | D8: Corporate | E8: Stewardship | F8: Active | G8: priya@ramanathan-assoc.com | H8: (617) 555-4102 | I8: Northeast | J8: Mid-Level | K8: 08/15/2022 | L8: 25000 | M8: 25000 | N8: 35000 | O8: 50000 | P8: 53200 | Q8: =SUM(M8:P8) -> 163200 | R8: No | X8: Direct | Y8: STEM Education | Z8: James Wright | AA8: 02/03/2026 | AB8: Email | AC8: Thank you + impact report | AD8: 04/15/2026 | AE8: No | AF8: No | AG8: 1 | AH8: C ($100K-$500K) | AI8: High | AJ8: 8 | AK8: Referred by Margaret Chen. Increased from $50K to $75K this year. | AL8: Jack
A9: F-008 | B9: Michael & Patricia Novak | C9: Novak Family Foundation | D9: Foundation | E9: Stewardship | F9: Active | G9: mnovak@novakfamilyfdn.org | H9: (847) 555-4412 | I9: Midwest | J9: Mid-Level | K9: 02/20/2021 | L9: 40000 | M9: 50000 | N9: 65000 | O9: 75000 | P9: 68400 | Q9: =SUM(M9:P9) -> 258400 | R9: No | X9: Novak Family DAF - Community Foundation | Y9: Pell-Eligible Student Scholarships | Z9: Sarah Mitchell | AA9: 03/18/2026 | AB9: Phone call | AC9: Prepare renewal proposal | AD9: 05/01/2026 | AE9: No | AF9: No | AG9: 1 | AH9: B ($500K-$1M) | AI9: High | AJ9: 7 | AK9: Focus on Pell-eligible students in Midwest. Opportunity for programmatic partnership. | AL9: Lisa
A10: F-009 | B10: Sandra Okonkwo | C10: Okonkwo Ventures | D10: Corporate | E10: Cultivation | F10: Prospect | G10: sokonkwo@okonkwoventures.com | H10: (404) 555-1357 | I10: Southeast | J10: Mid-Level | K10: 02/14/2026 | L10: 50000 | M10: 0 | N10: 0 | O10: 0 | P10: 41900 | Q10: =SUM(M10:P10) -> 41900 | R10: No | X10: Direct | Y10: Scholarship Program | Z10: Maria Lopez | AA10: 02/14/2026 | AB10: Event follow-up | AC10: Schedule discovery meeting | AD10: 04/20/2026 | AE10: No | AF10: No | AG10: 1 | AH10: C ($100K-$500K) | AI10: Medium | AJ10: 6 | AK10: Event follow-up conversion. Shares interest in scholarship program with Gutierrez-Santos. | AL10: Lisa
A11: F-010 | B11: Thomas Fitzgerald | C11: Fitzgerald & Moore LLP | D11: Corporate | E11: Stewardship | F11: Active | G11: tfitzgerald@fitzmoore.com | H11: (202) 555-9088 | I11: Mid-Atlantic | J11: Mid-Level | K11: 05/10/2020 | L11: 15000 | M11: 15000 | N11: 20000 | O11: 25000 | P11: 17500 | Q11: =SUM(M11:P11) -> 77500 | R11: No | X11: Direct | Y11: Unrestricted + Pro Bono Legal | Z11: James Wright | AA11: 03/01/2026 | AB11: In-person meeting | AC11: Discuss pro bono capacity for next FY | AD11: 04/30/2026 | AE11: No | AF11: No | AG11: 2 | AH11: C ($100K-$500K) | AI11: High | AJ11: 7 | AK11: Also provides pro bono legal support. Referred Robert Blackwell III. | AL11: Lisa
A12: F-011 | B12: William R. Thornton | C12: Thornton Capital Partners | D12: Corporate | E12: Qualification | F12: Prospect | G12: wthornton@thorntoncap.com | H12: (646) 555-5521 | I12: Northeast | J12: Mid-Level | K12: 10/05/2025 | L12: 60000 | M12: 0 | N12: 0 | O12: 60000 | P12: 38100 | Q12: =SUM(M12:P12) -> 98100 | R12: No | X12: Direct | Y12: Unrestricted | Z12: James Wright | AA12: 03/10/2026 | AB12: In-person meeting | AC12: Send introductory materials | AD12: 04/15/2026 | AE12: No | AF12: No | AG12: 2 | AH12: A ($1M+) | AI12: Medium | AJ12: 9 | AK12: Strong board prospect. Requested meeting with ED. Deepening engagement since fall reception. | AL12: Lisa
A13: F-012 | B13: Evelyn Tran | C13: Tran Holdings LLC | D13: Corporate | E13: Cultivation | F13: Prospect | G13: evelyn.tran@tranholdings.com | H13: (408) 555-2106 | I13: West Coast | J13: Entry | K13: 12/01/2025 | L13: 35000 | M13: 0 | N13: 0 | O13: 35000 | P13: 23000 | Q13: =SUM(M13:P13) -> 58000 | R13: No | X13: Direct | Y13: Alumni Scholarship | Z13: Sarah Mitchell | AA13: 03/22/2026 | AB13: Email | AC13: Follow up on named scholarship fund interest | AD13: 04/30/2026 | AE13: No | AF13: No | AG13: 1 | AH13: A ($1M+) | AI13: Low | AJ13: 7 | AK13: Alumni, Class of 2005. Company just completed Series C. Interested in named scholarship fund. | AL13: Lisa
A14: F-013 | B14: Hiroshi Tanaka | C14: Tanaka Biotech Inc. | D14: Corporate | E14: Identification | F14: Prospect | G14: htanaka@tanakabiotech.com | H14: (858) 555-3891 | I14: West Coast | J14: None | M14: 0 | N14: 0 | O14: 0 | P14: 0 | Q14: =SUM(M14:P14) -> 0 | R14: No | Y14: STEM Education | Z14: Maria Lopez | AA14: 01/10/2026 | AB14: Research | AC14: Request intro through Margaret Chen | AD14: 04/15/2026 | AE14: No | AF14: No | AG14: 0 | AH14: A ($1M+) | AI14: Low | AJ14: 7 | AK14: UC San Diego connection. Biotech IPO 2024. Interested in STEM education per public statements. | AL14: Lisa
A15: F-014 | B15: Denise & Marcus Hargrove | C15: Hargrove Family Fund | D15: Individual/Family | E15: Identification | F15: Prospect | G15: dhargrove@hargrovefund.org | H15: (404) 555-8822 | I15: Southeast | J15: None | M15: 0 | N15: 0 | O15: 0 | P15: 0 | Q15: =SUM(M15:P15) -> 0 | R15: No | Z15: James Wright | AA15: 12/15/2025 | AB15: Research | AC15: Research capacity and interests | AD15: 05/01/2026 | AE15: No | AF15: No | AG15: 0 | AH15: B ($500K-$1M) | AI15: Low | AJ15: 7 | AK15: Atlanta-based philanthropy family. Focus on education equity. Identified via peer screening. | AL15: Jack
A16: F-015 | B16: Victoria Langston-Reed | C16: Reed Foundation | D16: Foundation | E16: Solicitation | F16: Prospect | G16: vlreed@reedfoundation.org | H16: (617) 555-6100 | I16: Northeast | J16: None | M16: 0 | N16: 0 | O16: 0 | P16: 0 | Q16: =SUM(M16:P16) -> 0 | R16: No | Y16: Scholarship / General | Z16: Sarah Mitchell | AA16: 03/28/2026 | AB16: Proposal submitted | AC16: Await foundation board decision | AD16: 06/01/2026 | AE16: No | AF16: No | AG16: 1 | AH16: A ($1M+) | AI16: Medium | AJ16: 6 | AK16: $200K proposal submitted for scholarship endowment. Foundation board meets quarterly. | AL16: Lisa
A17: F-016 | B17: Gregory & Susan Patel | C17: Patel Family Trust | D17: Individual/Family | E17: Re-engagement | F17: Lapsed | G17: gpatel@patelfamilytrust.org | H17: (312) 555-2200 | I17: Midwest | J17: Mid-Level | K17: 06/01/2018 | L17: 25000 | M17: 50000 | N17: 40000 | O17: 0 | P17: 0 | Q17: =SUM(M17:P17) -> 90000 | R17: No | X17: Patel Family DAF - Schwab | Y17: Unrestricted | Z17: James Wright | AA17: 11/20/2025 | AB17: Phone call (voicemail) | AC17: Send personalized re-engagement letter | AD17: 04/10/2026 | AE17: No | AF17: Yes (Former) | AG17: 0 | AH17: B ($500K-$1M) | AI17: Medium | AJ17: 8 | AK17: Last gift FY2024. Missed FY2025 renewal. Was on advisory council. Personal outreach needed. | AL17: Rafaela
A18: F-017 | B18: Diana Kowalski | C18: Kowalski Media Group | D18: Corporate | E18: Re-engagement | F18: Lapsed | G18: dkowalski@kowalskimedia.com | H18: (646) 555-4477 | I18: Northeast | J18: Entry | K18: 09/15/2020 | L18: 10000 | M18: 15000 | N18: 10000 | O18: 0 | P18: 0 | Q18: =SUM(M18:P18) -> 25000 | R18: No | X18: Direct | Y18: Unrestricted | Z18: Maria Lopez | AA18: 10/01/2025 | AB18: Email (no response) | AC18: Try phone outreach | AD18: 04/15/2026 | AE18: No | AF18: No | AG18: 0 | AH18: C ($100K-$500K) | AI18: Low | AJ18: 4 | AK18: Last gift FY2024. No response to renewal emails. Try phone. | AL18: Jack
A19: F-018 | B19: Lawrence Bennett | C19: Bennett Capital LLC | D19: Corporate | E19: Closed - Declined | F19: Inactive | G19: lbennett@bennettcap.com | H19: (415) 555-9900 | I19: West Coast | J19: None | M19: 0 | N19: 0 | O19: 0 | P19: 0 | Q19: =SUM(M19:P19) -> 0 | R19: No | Z19: Sarah Mitchell | AA19: 09/15/2025 | AB19: Phone call | AC19: Monitor; revisit in 18 months | AD19: 03/15/2027 | AE19: No | AF19: No | AG19: 1 | AH19: A ($1M+) | AI19: Very Low | AJ19: 7 | AK19: Declined after solicitation meeting. Cited other philanthropic priorities. Polite; door not closed. | AL19: Rafaela
A20: F-019 | B20: Catherine & James Moreau | C20: Moreau Foundation | D20: Foundation | E20: Stewardship | F20: Active | G20: cmoreau@moreaufoundation.org | H20: (504) 555-3321 | I20: Southeast | J20: Major | K20: 01/10/2019 | L20: 80000 | M20: 100000 | N20: 120000 | O20: 140000 | P20: 116500 | Q20: =SUM(M20:P20) -> 476500 | R20: Yes | S20: 800000 | T20: FY2024 | U20: FY2028 | V20: 3 of 5 | W20: 160000 | X20: Moreau Foundation DAF - Fidelity | Y20: First-Generation Student Support | Z20: Sarah Mitchell | AA20: 03/20/2026 | AB20: Phone call | AC20: Prepare cultivation strategy | AD20: 05/10/2026 | AE20: No | AF20: No | AG20: 2 | AH20: B ($500K-$1M) | AI20: Very High | AJ20: 9 | AK20: New Orleans-based. Deep interest in first-gen students. Annual site visits. | AL20: Jack
A21: F-020 | B21: Richard Cheng | C21: Cheng Dynamics | D21: Corporate | E21: Stewardship | F21: Active | G21: rcheng@chengdynamics.com | H21: (650) 555-8812 | I21: West Coast | J21: Mid-Level | K21: 03/01/2022 | L21: 30000 | M21: 30000 | N21: 45000 | O21: 55000 | P21: 49600 | Q21: =SUM(M21:P21) -> 179600 | R21: No | X21: Direct | Y21: STEM Education | Z21: Maria Lopez | AA21: 02/20/2026 | AB21: Email | AC21: Draft stewardship plan | AD21: 04/20/2026 | AE21: No | AF21: No | AG21: 2 | AH21: C ($100K-$500K) | AI21: High | AJ21: 5 | AK21: Growing engagement. Employee matching program potential. | AL21: Rafaela
A22: F-021 | B22: Amara Osei-Mensah | C22: Osei-Mensah Family Trust | D22: Individual/Family | E22: Stewardship | F22: Active | G22: aosei@oseimensah.org | H22: (770) 555-6644 | I22: Southeast | J22: Mid-Level | K22: 06/15/2021 | L22: 25000 | M22: 35000 | N22: 40000 | O22: 50000 | P22: 53200 | Q22: =SUM(M22:P22) -> 178200 | R22: No | X22: Osei-Mensah DAF - Vanguard | Y22: Scholarship Program | Z22: James Wright | AA22: 01/30/2026 | AB22: In-person meeting | AC22: Propose multi-year pledge | AD22: 04/25/2026 | AE22: No | AF22: No | AG22: 1 | AH22: B ($500K-$1M) | AI22: High | AJ22: 9 | AK22: Atlanta-based. Increasing annually. Ready for major gift conversation. | AL22: Jack
A23: F-022 | B23: Patricia & Leonard Dubois | C23: Dubois Charitable Fund | D23: Individual/Family | E23: Solicitation | F23: Active | G23: pdubois@duboisfund.org | H23: (617) 555-1198 | I23: Northeast | J23: Major | K23: 09/01/2017 | L23: 75000 | M23: 100000 | N23: 100000 | O23: 100000 | P23: 69800 | Q23: =SUM(M23:P23) -> 369800 | R23: Yes | S23: 500000 | T23: FY2023 | U23: FY2027 | V23: 4 of 5 | W23: 100000 | X23: Dubois DAF - BNY Mellon | Y23: Unrestricted | Z23: Sarah Mitchell | AA23: 12/15/2025 | AB23: Holiday card + call | AC23: Final pledge year discussion; renewal strategy | AD23: 06/01/2026 | AE23: Yes | AF23: No | AG23: 2 | AH23: A ($1M+) | AI23: Very High | AJ23: 10 | AK23: Board member. Entering final pledge year. Need to discuss renewal or increase. | AL23: Lisa
A24: F-023 | B24: Kenji & Yuki Watanabe | C24: Watanabe Group | D24: Corporate | E24: Cultivation | F24: Active | G24: kwatanabe@watanabegroup.co | H24: (206) 555-4455 | I24: Pacific NW | J24: Mid-Level | K24: 11/15/2024 | L24: 40000 | M24: 0 | N24: 0 | O24: 40000 | P24: 36900 | Q24: =SUM(M24:P24) -> 76900 | R24: No | X24: Direct | Y24: Rural Program | Z24: Maria Lopez | AA24: 03/01/2026 | AB24: In-person meeting | AC24: Tour rural program sites | AD24: 05/15/2026 | AE24: No | AF24: No | AG24: 1 | AH24: C ($100K-$500K) | AI24: Medium | AJ24: 6 | AK24: Seattle-based. Second gift indicates deepening. Schedule site visit. | AL24: Lisa
A25: F-024 | B25: Helen Markovich | C25: Markovich Partners LLC | D25: Corporate | E25: Stewardship | F25: Active | G25: hmarkovich@markovichpartners.com | H25: (312) 555-7733 | I25: Midwest | J25: Mid-Level | K25: 04/20/2020 | L25: 20000 | M25: 25000 | N25: 30000 | O25: 35000 | P25: 36900 | Q25: =SUM(M25:P25) -> 126900 | R25: No | X25: Direct | Y25: Unrestricted | Z25: James Wright | AA25: 02/10/2026 | AB25: Email | AC25: Send FY2026 impact summary | AD25: 04/15/2026 | AE25: No | AF25: Yes | AG25: 2 | AH25: C ($100K-$500K) | AI25: High | AJ25: 7 | AK25: Advisory council member. Consistent growth. Midwest business network connections. | AL25: Lisa
A26: F-025 | B26: Raj & Sunita Kapoor | C26: Kapoor Family Foundation | D26: Foundation | E26: Solicitation | F26: Active | G26: rkapoor@kapoorfamilyfdn.org | H26: (713) 555-9922 | I26: Southwest | J26: Major | K26: 02/28/2020 | L26: 50000 | M26: 75000 | N26: 90000 | O26: 100000 | P26: 84300 | Q26: =SUM(M26:P26) -> 349300 | R26: Yes | S26: 600000 | T26: FY2025 | U26: FY2029 | V26: 2 of 5 | W26: 120000 | X26: Kapoor Family DAF - Goldman Sachs | Y26: STEM Education Pipeline | Z26: Maria Lopez | AA26: 03/10/2026 | AB26: Phone call | AC26: Initial outreach call | AD26: 04/10/2026 | AE26: No | AF26: No | AG26: 2 | AH26: A ($1M+) | AI26: High | AJ26: 8 | AK26: Houston-based. Strong alignment with STEM pipeline. Want to see expansion to Texas. | AL26: Lisa
A27: F-026 | B27: Franklin & Anne Beaumont | C27: Beaumont Group | D27: Individual/Family | E27: Solicitation | F27: Prospect | G27: fbeaumont@beaumontgroup.com | H27: (214) 555-2288 | I27: Southwest | J27: Mid-Level | K27: 07/01/2021 | L27: 20000 | M27: 25000 | N27: 30000 | O27: 40000 | P27: 38400 | Q27: =SUM(M27:P27) -> 133400 | R27: No | X27: Direct | Y27: General Scholarship | Z27: Sarah Mitchell | AA27: 01/15/2026 | AB27: Holiday card + call | AC27: Annual renewal ask | AD27: 09/01/2026 | AE27: No | AF27: No | AG27: 1 | AH27: C ($100K-$500K) | AI27: High | AJ27: 7 | AK27: Dallas-based. Reliable renewals. Potential for multi-year commitment. | AL27: Jack
A28: F-027 | B28: Nadia El-Amin | C28: El-Amin Consulting Group | D28: Corporate | E28: Stewardship | F28: Active | G28: nelamin@elamingroup.com | H28: (202) 555-6655 | I28: Mid-Atlantic | J28: Entry | K28: 10/01/2023 | L28: 10000 | M28: 0 | N28: 0 | O28: 10000 | P28: 12300 | Q28: =SUM(M28:P28) -> 22300 | R28: No | X28: Direct | Y28: Unrestricted | Z28: James Wright | AA28: 03/15/2026 | AB28: Email | AC28: Cultivation lunch | AD28: 05/01/2026 | AE28: No | AF28: No | AG28: 1 | AH28: C ($100K-$500K) | AI28: Medium | AJ28: 7 | AK28: DC-based consultant. Growing engagement. Connected to policy networks. | AL28: Lisa
A29: F-028 | B29: George & Linda Stratton | C29: Stratton Industries | D29: Corporate | E29: Qualification | F29: Prospect | G29: gstratton@strattonindustries.com | H29: (704) 555-1122 | I29: Southeast | J29: None | M29: 0 | N29: 0 | O29: 0 | P29: 0 | Q29: =SUM(M29:P29) -> 0 | R29: No | Y29: Unrestricted | Z29: James Wright | AA29: 02/01/2026 | AB29: Research | AC29: Request meeting through Thornton connection | AD29: 04/20/2026 | AE29: No | AF29: No | AG29: 0 | AH29: A ($1M+) | AI29: Low | AJ29: 7 | AK29: Charlotte manufacturing. Peer connection through William Thornton. Philanthropic history in education. | AL29: Lisa
A30: F-029 | B30: Isabelle Fontaine | C30: Fontaine Arts & Education Trust | D30: Foundation | E30: Cultivation | F30: Prospect | G30: ifontaine@fontainetrust.org | H30: (415) 555-5567 | I30: West Coast | J30: None | M30: 0 | N30: 0 | O30: 0 | P30: 0 | Q30: =SUM(M30:P30) -> 0 | R30: No | Y30: Arts + STEM Integration | Z30: Sarah Mitchell | AA30: 03/25/2026 | AB30: In-person meeting | AC30: Submit LOI for arts-STEM integration grant | AD30: 05/01/2026 | AE30: No | AF30: No | AG30: 1 | AH30: B ($500K-$1M) | AI30: Medium | AJ30: 5 | AK30: SF-based trust focused on arts and education. Met at conference. Very aligned with new arts-STEM program. | AL30: Lisa
A31: F-030 | B31: Marcus & Tanya Robinson | C31: Robinson Legacy Fund | D31: Individual/Family | E31: Identification | F31: Prospect | G31: mrobinson@robinsonlegacy.org | H31: (404) 555-8890 | I31: Southeast | J31: None | M31: 0 | N31: 0 | O31: 0 | P31: 0 | Q31: =SUM(M31:P31) -> 0 | R31: No | Z31: Maria Lopez | AA31: 01/20/2026 | AB31: Research | AC31: Add to annual gala invite list | AD31: 04/15/2026 | AE31: No | AF31: No | AG31: 0 | AH31: B ($500K-$1M) | AI31: Low | AJ31: 6 | AK31: Atlanta philanthropists. Education equity focus. Identified through Hargrove network. | AL31: Jack
A32: F-031 | B32: Dr. Angela Vasquez-Torres | C32: Vasquez-Torres Medical Foundation | D32: Foundation | E32: Solicitation | F32: Prospect | G32: avasquez@vtmedfoundation.org | H32: (305) 555-7712 | I32: Southeast | J32: None | M32: 0 | N32: 0 | O32: 0 | P32: 0 | Q32: =SUM(M32:P32) -> 0 | R32: No | Y32: Health Sciences Scholarship | Z32: James Wright | AA32: 03/30/2026 | AB32: Proposal submitted | AC32: Follow up after board review | AD32: 06/15/2026 | AE32: No | AF32: No | AG32: 1 | AH32: B ($500K-$1M) | AI32: Medium | AJ32: 5 | AK32: $150K proposal for health sciences scholarships. Miami-based. Board meets in June. | AL32: Rafaela
A33: F-032 | B33: Arthur & Elaine Worthington | C33: Worthington Trust | D33: Individual/Family | E33: Qualification | F33: Prospect | G33: aworthington@worthingtontrust.com | H33: (860) 555-3344 | I33: Northeast | J33: None | M33: 0 | N33: 0 | O33: 0 | P33: 0 | Q33: =SUM(M33:P33) -> 0 | R33: No | Y33: Endowment | Z33: Sarah Mitchell | AA33: 02/10/2026 | AB33: Phone call | AC33: Schedule campus visit | AD33: 04/25/2026 | AE33: No | AF33: No | AG33: 0 | AH33: A ($1M+) | AI33: Low | AJ33: 5 | AK33: Connecticut old money. Endowment-focused giving. Warm intro from Dubois. | AL33: Lisa
A34: F-033 | B34: Carmen Delgado-Ruiz | C34: Delgado Enterprises | D34: Corporate | E34: Qualification | F34: Prospect | G34: cdelgado@delgadoenterprises.com | H34: (210) 555-4411 | I34: Southwest | J34: Entry | K34: 12/15/2025 | L34: 15000 | M34: 0 | N34: 0 | O34: 0 | P34: 10000 | Q34: =SUM(M34:P34) -> 10000 | R34: No | X34: Direct | Y34: STEM Education | Z34: Maria Lopez | AA34: 12/15/2025 | AB34: Event follow-up | AC34: Schedule coffee meeting | AD34: 04/15/2026 | AE34: No | AF34: No | AG34: 1 | AH34: C ($100K-$500K) | AI34: Medium | AJ34: 4 | AK34: San Antonio-based. Initial gift at holiday event. Tech company founder. STEM aligned. | AL34: Rafaela
A35: F-034 | B35: Howard & Jean Prescott | C35: Prescott Foundation | D35: Foundation | E35: Re-engagement | F35: Lapsed | G35: hprescott@prescottfdn.org | H35: (203) 555-6677 | I35: Northeast | J35: Major | K35: 03/01/2016 | L35: 100000 | M35: 120000 | N35: 100000 | O35: 50000 | P35: 0 | Q35: =SUM(M35:P35) -> 270000 | R35: No | X35: Prescott DAF - Northern Trust | Y35: Unrestricted | Z35: Sarah Mitchell | AA35: 11/01/2025 | AB35: Phone call | AC35: ED personal outreach call | AD35: 04/10/2026 | AE35: No | AF35: Yes (Former) | AG35: 0 | AH35: A ($1M+) | AI35: Medium | AJ35: 8 | AK35: Declined from $120K to $50K in FY2025, then lapsed. Former advisory council. Personal call from ED needed. | AL35: Lisa
A36: F-035 | B36: Tomoko Nakamura | C36: Nakamura Design Studio | D36: Corporate | E36: Re-engagement | F36: Lapsed | G36: tnakamura@nakamuradesign.com | H36: (503) 555-2233 | I36: Pacific NW | J36: Entry | K36: 08/01/2022 | L36: 10000 | M36: 10000 | N36: 15000 | O36: 10000 | P36: 0 | Q36: =SUM(M36:P36) -> 35000 | R36: No | X36: Direct | Y36: Unrestricted | Z36: Maria Lopez | AA36: 09/15/2025 | AB36: Email (no response) | AC36: Send personalized project update | AD36: 04/15/2026 | AE36: No | AF36: No | AG36: 0 | AH36: C ($100K-$500K) | AI36: Low | AJ36: 5 | AK36: Portland designer. Gave 3 years. No response to renewal. Try project-specific appeal. | AL36: Rafaela
A37: F-036 | B37: Robert & Christine Andersen | C37: Andersen Family Fund | D37: Individual/Family | E37: Re-engagement | F37: Lapsed | G37: randersen@andersenfund.org | H37: (952) 555-8811 | I37: Midwest | J37: Mid-Level | K37: 05/15/2019 | L37: 30000 | M37: 40000 | N37: 50000 | O37: 0 | P37: 0 | Q37: =SUM(M37:P37) -> 90000 | R37: No | X37: Andersen DAF - Schwab | Y37: Pell-Eligible Scholarships | Z37: James Wright | AA37: 10/20/2025 | AB37: Phone call (voicemail) | AC37: Handwritten note from scholarship recipient | AD37: 04/20/2026 | AE37: No | AF37: No | AG37: 0 | AH37: B ($500K-$1M) | AI37: Medium | AJ37: 7 | AK37: Minneapolis family. Cared about Pell students. Missed FY2025. Try scholarship recipient story. | AL37: Lisa
A38: F-037 | B38: Martin & Louise Kessler | C38: Kessler Group | D38: Corporate | E38: Closed - Declined | F38: Inactive | G38: mkessler@kesslergroup.com | H38: (212) 555-0099 | I38: Northeast | J38: None | M38: 0 | N38: 0 | O38: 0 | P38: 0 | Q38: =SUM(M38:P38) -> 0 | R38: No | Z38: James Wright | AA38: 06/01/2025 | AB38: In-person meeting | AC38: Revisit in 2027 | AD38: 01/15/2027 | AE38: No | AF38: No | AG38: 0 | AH38: A ($1M+) | AI38: Very Low | AJ38: 7 | AK38: Declined. Company restructuring. Said to revisit in 2 years. | AL38: Jack
A39: F-038 | B39: Diane Zhao | C39: Zhao Capital Management | D39: Corporate | E39: Closed - Declined | F39: Inactive | G39: dzhao@zhaocapital.com | H39: (646) 555-3388 | I39: Northeast | J39: None | M39: 0 | N39: 0 | O39: 0 | P39: 0 | Q39: =SUM(M39:P39) -> 0 | R39: No | Z39: Sarah Mitchell | AA39: 08/15/2025 | AB39: Email | AC39: Initial outreach call | AD39: 08/15/2026 | AE39: No | AF39: No | AG39: 1 | AH39: B ($500K-$1M) | AI39: Very Low | AJ39: 3 | AK39: Politely declined. Prefers arts funding. Keep on radar for arts-STEM if program launches. | AL39: Lisa
A40: F-039 | B40: Jonathan & Claire Harrington | C40: Harrington Charitable Trust | D40: Individual/Family | E40: Stewardship | F40: Active | G40: jharrington@harringtontrust.org | H40: (617) 555-8834 | I40: Northeast | J40: Major | K40: 05/20/2018 | L40: 60000 | M40: 80000 | N40: 90000 | O40: 100000 | P40: 88900 | Q40: =SUM(M40:P40) -> 358900 | R40: Yes | S40: 550000 | T40: FY2025 | U40: FY2029 | V40: 2 of 5 | W40: 110000 | X40: Harrington DAF - Fidelity | Y40: First-Generation Students | Z40: Sarah Mitchell | AA40: 03/01/2026 | AB40: In-person meeting | AC40: Annual pledge check-in | AD40: 05/20/2026 | AE40: No | AF40: Yes | AG40: 3 | AH40: A ($1M+) | AI40: High | AJ40: 8 | AK40: Boston-based. Advisory council. Strong advocates. Host annual donor dinner. | AL40: Jack
...

Sheet Pipeline Summary
A1: Funder Pipeline Summary
A3: By Status | B3: Count | C3: Total Lifetime Giving
A4: Active | B4: =COUNTIF('Funder Database April'!F:F,"Active") -> 28 | C4: =SUMIF('Funder Database April'!F:F,"Active",'Funder Database April'!Q:Q) -> 8060000
A5: Prospect | B5: =COUNTIF('Funder Database April'!F:F,"Prospect") -> 35 | C5: =SUMIF('Funder Database April'!F:F,"Prospect",'Funder Database April'!Q:Q) -> 325000
A6: Lapsed | B6: =COUNTIF('Funder Database April'!F:F,"Lapsed") -> 9 | C6: =SUMIF('Funder Database April'!F:F,"Lapsed",'Funder Database April'!Q:Q) -> 755000
A7: Inactive | B7: =COUNTIF('Funder Database April'!F:F,"Inactive") -> 8 | C7: =SUMIF('Funder Database April'!F:F,"Inactive",'Funder Database April'!Q:Q) -> 0
A8: Total | B8: =SUM(B4:B7) -> 80 | C8: =SUM(C4:C7) -> 9140000
A10: By Stage | B10: Count
A11: Identification | B11: =COUNTIF('Funder Database April'!E:E,"Identification") -> 10
A12: Qualification | B12: =COUNTIF('Funder Database April'!E:E,"Qualification") -> 8
A13: Cultivation | B13: =COUNTIF('Funder Database April'!E:E,"Cultivation") -> 15
A14: Solicitation | B14: =COUNTIF('Funder Database April'!E:E,"Solicitation") -> 6
A15: Stewardship | B15: =COUNTIF('Funder Database April'!E:E,"Stewardship") -> 24
A16: Re-engagement | B16: =COUNTIF('Funder Database April'!E:E,"Re-engagement") -> 9
A17: Closed - Declined | B17: =COUNTIF('Funder Database April'!E:E,"Closed - Declined") -> 8
A19: FY2026 YTD Giving | B19: =SUM('Funder Database April'!P:P) -> 2925000
